Workbook
Name BASE_PORCENTAJES: 'PORCENTAJES FACTORES'!$B$1:$N$981
Name DTS: #REF!
Name DTS: #REF!
Name DTS: #REF!
Name DTS: #REF!
Name PLANTA_PERNO: 'PLANTA PERNO'!$A$9:$AP$828
Name PLANTA_PERSONAL_SJD: 'PLANTA SJD (2)'!$A$4:$AR$174
Name PLANTA_PERSONAL_SJD: 'PLANTA SJD'!$A$4:$AP$174

Sheet Hoja4 (2)
A1: CEDULA | B1: APELLIDOS Y NOMBRES | C1: TIPO DE VINCULACIÓN A LA ENTIDAD | D1: CEDULA | E1: TITULAR CARGO | F1: NIVEL | G1: NOMENCLATURA_ADMIN | H1: CÓDIGO | I1: GRADO | J1: U | K1: DEPENDENCIA DEL CARGO | L1: PROPOSITO | M1: FUNCIONES | N1: REQUISITOS | O1: Páginas Manual de Funciones
A2: 33368317 | B2: ZULY NATALIA NANDAR CASTAÑEDA | C2: PROVISIONALIDAD | E2: VACANTE DEFINITIVA | F2: ASISTENCIAL | G2: SECRETARIO | H2: 440 | I2: 9 | J2: 440-9 | K2: DIRECCIÓN DISTRITAL DE POLÍTICA JURÍDICA | L2: Realizar las labores secretariales como apoyo a la gestión de la dependencia, con oportunidad y eficiencia para satisfacer las necesidades. | M2: 1. Efectuar el envío y la recepción de los documentos y de la correspondencia relacionados con asuntos de competencia del área de trabajo, de acuerdo con las normas y procedimientos respectivos. 2. Custodiar y actualizar el archivo asignado conforme a instrucciones recibidas y con la eficiencia y oportunidad requerida. 3. Elaborar oficios y memorandos para dar trámite a las solicitudes presentadas, conforme a las instrucciones impartidas por el jefe inmediato. 4. Elaborar los informes que le sean requeridos por el jefe inmediato con criterios de oportunidad y efectividad. 5. Prestar atención telefónica y presencial sobre los trámites que adelanta la dependencia con oportunidad y veracidad 6. Desempeñar las demás funciones que le asigne el superior inmediato de acuerdo a la naturaleza del cargo. | N2: Estudio: Aprobación de cuatro (4) años de educación básica secundaria. | O2: 310-311 RES. 020 de 2019
A3: 52699744 | B3: MARIA CATALINA JARAMILLO GONZALEZ | C3: LIBRE NOMBRAMIENTO Y REMOCIÓN | D3: 52699744 | E3: MARIA CATALINA JARAMILLO GONZALEZ | F3: DIRECTIVO | G3: DIRECTOR TÉCNICO | H3: 9 | I3: 7 | J3: 9-7 | K3: DIRECCIÓN DISTRITAL DE POLÍTICA JURÍDICA | L3: Dirigir y coordinar la elaboración de estudios, diagnósticos y análisis jurídicos y jurisprudenciales que se adelanten, así como efectuar su revisión y proponer la adopción de políticas y lineamientos jurídicos, de impacto para el Distrito Capital. | M3: 1. Dirigir en la definición y coordinación de la gestión jurídica Distrital en materia de estudios y análisis especializados, coordinación del cuerpo de abogados del Distrito Capital y gestión de la información jurídica con la oportunidad requerida. 2. Dirigir los estudios, análisis jurisprudenciales y doctrinales, e investigaciones jurídicas en temáticas de interés para el Distrito Capital, en beneficio de la gestión de las oficinas jurídicas o las dependencias que hagan sus veces, en las entidades y organismos distritales con criterios de oportunidad y efectividad. 3. Coordinar la realización de actividades académicas y de formación para el fortalecimiento de las competencias jurídicas del Cuerpo de Abogados del Distrito Capital con la eficacia y oportunidad requerida 4. Asesorar a la Secretaría Jurídica Distrital en la formulación y desarrollo de la política de coordinación jurídica de las entidades y organismos del Distrito Capital. 5. Dirigir la elaboración de los proyectos de política en materia de contratación y demás temas jurídicos de interés para el Distrito, buscando la unificación de criterios para la aplicación de las normas y la ejecución concertada de acciones en esta materia, para que sean adoptados por la Secretaría Jurídica Distrital. 6. Coordinar el diseño e implementación de las políticas de divulgación del ordenamiento normativo y de acceso a la información jurídica promoviendo información veraz y actualizada.. 7. Orientar en el desarrollo, mantenimiento e implementación de los sistemas de información jurídica, en procura que los mismos estén permanentemente actualizados y disponibles para las entidades y organismos distritales y la ciudadanía en general. 8. Asistir al/la Secretario/a Jurídico/a Distrital y al/la Subsecretario/a Jurídico/a Distrital en todos los trámites, requisitos y procedimientos relacionados con las Asociaciones Público Privadas. 9. Dirigir y proponer lineamientos de unificación jurídica cuando exista disparidad de criterios en las entidades distritales con la eficacia requerida. 10. Administrar y dirigir la actualización y operación de los sistemas de información jurídica que la Secretaría Jurídica Distrital establezca para el control y operatividad de la gestión jurídica distrital, que no se encuentren a cargo de otra Dirección. 11. Asistir y apoyar a la Secretaría Jurídica Distrital y la Subsecretaría Jurídica Distrital en el ejercicio de sus funciones y atribuciones legales 12. Dirigir estudios, investigaciones y estrategias para el diseño de políticas en materia de prevención del daño antijurídico que se relacionen con los temas competencia de la dirección con la oportunidad requerida. 13. Dirigir el análisis y determinar la vigencia de los actos administrativos y directrices expedidos por el Alcalde Mayor, conforme al procedimiento establecido por la Secretaría Jurídica Distrital. 14. Asesorar jurídicamente a las dependencias de la Secretaría Jurídica Distrital en los temas de su competencia. 15. Desempeñar las demás funciones que le asigne el superior inmediato de acuerdo a la naturaleza del cargo. | N3: Titulo profesional en disciplina academica del núcleo básico de conocimiento en Derecho y afines. Titulo de posgrado en áreas relacionadas con la funciones del cargo. Tarjeta o matrícula profesional en los casos reglamentados por la Ley. | O3: 20-23 RES. 085 de 2020
A4: 52363895 | B4: ELVIRA LILIANA HERNANDEZ LIBREROS | C4: CARRERA ADMINISTRATIVA | D4: 52363895 | E4: ELVIRA LILIANA HERNANDEZ LIBREROS | F4: PROFESIONAL | G4: PROFESIONAL ESPECIALIZADO | H4: 222 | I4: 27 | J4: 222-27 | K4: DIRECCIÓN DISTRITAL DE POLÍTICA JURÍDICA | L4: Realizar los estudios, diagnósticos y análisis normativos, jurisprudenciales y doctrinales en temas de relevancia o de interés Distrital con el fin de contribuir en la formulación de alternativas jurídicas viables que contribuyan al fortalecimiento de la defensa judicial, la prevención del daño antijurídico y la estructuración de fórmulas tendientes a la materialización de la gestión jurídica pública. | M4: 1. Asesorar y elaborar los estudios para la formulación de los lineamientos de política en gerencia jurídica que contribuyan a la prevención del daño antijurídico. 2. Realizar investigaciones, estudios, diagnósticos en derecho público sobre temáticas de alto impacto para la ciudad, que le sean asignados y presentar los informes y evaluaciones correspondientes, con criterios de calidad y oportunidad. 3. Realizar análisis jurisprudencial de las decisiones judiciales en temáticas de derecho público asignadas y elaborar las fichas correspondientes en los sistemas de información jurídica, con eficacia y oportunidad. 4. Elaborar las recomendaciones tendientes a fortalecer la defensa judicial y la prevención del daño antijurídico en el Distrito Capital, acorde con la normatividad vigente. 5. Realizar seguimiento a las iniciativas, decisiones judiciales o temáticas jurídicas de interés para el Distrito capital, a fin de prevenir situaciones críticas que puedan ser atendidas oportunamente. 6. Proyectar conceptos jurídicos solicitados por las entidades u organismos Distritales y el superior inmediato, de acuerdo con la normatividad y jurisprudencia vigente y dentro de la oportunidad requerida. 7. Elaborar anteproyectos de ley, acuerdos, decretos, resoluciones y demás actos administrativos de manera oportuna, que se deriven como producto de los estudios e investigaciones jurídicas que se realicen. 8. Elaborar informes que se soliciten, sobre las actividades desarrolladas con la oportunidad y periodicidad requerida. 9. Participar en los mesas de trabajos, consejos, y/o comités, levantar las actas correspondientes, e informar al jefe inmediato sobre las conclusiones del mismo. 10. Desempeñar las demás funciones que le asigne el superior inmediato de acuerdo a la naturaleza del cargo. | N4: Estudio: Título profesional en: Derecho; Derecho y Ciencias Sociales; Derecho y Ciencias Políticas; Derecho y Ciencias Humanas; Derecho y Ciencias Administrativas; Derecho Ciencias Políticas y Relaciones Internacionales; Jurisprudencia; Justicia y Derecho; ó Leyes y Jurisprudencia; del núcleo básico de conocimiento en Derecho y afines. Título de postgrado en áreas relacionadas con las funciones del cargo. Tarjeta o matricula profesional en los casos reglamentados por la Ley. | O4: 66-68 RES. 020 de 2019
A5: 64586540 | B5: ALMA ROSA RAMOS MARIA | C5: CARRERA ADMINISTRATIVA | D5: 64586540 | E5: ALMA ROSA RAMOS MARIA | F5: PROFESIONAL | G5: PROFESIONAL ESPECIALIZADO | H5: 222 | I5: 27 | J5: 222-27 | K5: DIRECCIÓN DISTRITAL DE POLÍTICA JURÍDICA | L5: realizar los estudios, diagnósticos y análisis normativos, jurisprudenciales y doctrinales en temas de relevancia o de interés distrital con el fin de contribuir en la formulación de alternativas jurídicas viables que contribuyan al fortalecimiento de la defensa judicial, la prevención del daño antijurídico y la estructuración de fórmulas tendientes a la materialización de la gestión jurídica pública. | M5: 1.Asesorar y elaborar los estudios para la formulación de los lineamientos de política en gerencia jurídica que contribuyan a la prevención del daño antijurídico. 2.Realizar investigaciones, estudios, diagnósticos en derecho público sobre temáticas de alto impacto para la ciudad, que le sean asignados y presentar los informes y evaluaciones correspondientes, con criterios de calidad y oportunidad. 3.Realizar análisis jurisprudencial de las decisiones judiciales en temáticas de derecho público asignadas y elaborar las fichas correspondientes en los sistemas de información jurídica, con eficacia y oportunidad. 4.Elaborar las recomendaciones tendientes a fortalecer la defensa judicial y la prevención del daño antijurídico en el Distrito Capital, acorde con la normatividad vigente. 5.Realizar seguimiento a las iniciativas, decisiones judiciales o temáticas jurídicas de interés para el Distrito capital, a fin de prevenir situaciones críticas que puedan ser atendidas oportunamente. 6.Proyectar conceptos jurídicos solicitados por las entidades u organismos Distritales y el superior inmediato, de acuerdo con la normatividad y jurisprudencia vigente y dentro de la oportunidad requerida. 7.Elaborar anteproyectos de ley, acuerdos, decretos, resoluciones y demás actos administrativos de manera oportuna, que se deriven como producto de los estudios e investigaciones jurídicas que se realicen. 8.Elaborar informes que se soliciten, sobre las actividades desarrolladas con la oportunidad y periodicidad requerida. 9.Participar en los mesas de trabajos, consejos, y/o comités, levantar las actas correspondientes, e informar al jefe inmediato sobre las conclusiones del mismo. 10.Desempeñar las demás funciones que le asigne el superior inmediato de acuerdo a la naturaleza del cargo. | N5: Estudio: Título profesional en: Derecho; Derecho y Ciencias Sociales; Derecho y Ciencias Políticas; Derecho y Ciencias Humanas; Derecho y Ciencias Administrativas; Derecho Ciencias Políticas y Relaciones Internacionales; Jurisprudencia; Justicia y Derecho; ó Leyes y Jurisprudencia; del núcleo básico de conocimiento en Derecho y afines. Título de postgrado en áreas relacionadas con las funciones del cargo. Tarjeta o matricula profesional en los casos reglamentados por la Ley. | O5: 66-68 RES. 020 de 2019
A6: 73155098 | B6: FERNAN ENRIQUE PEREZ FORTICH | C6: CARRERA ADMINISTRATIVA | D6: 53015269 | E6: JOHANA PATRICIA GAMEZ GOMEZ | F6: PROFESIONAL | G6: PROFESIONAL ESPECIALIZADO | H6: 222 | I6: 22 | J6: 222-22 | K6: DIRECCIÓN DISTRITAL DE POLÍTICA JURÍDICA | L6: desarrollar estudios jurídicos en temas de impacto distrital y proponer alternativas de solución en el marco de la coordinación jurídica distrital para el fortalecimiento de la gestión jurídica pública en bogotá, d.c. | M6: 1.Realizar el seguimiento a las actividades de implementación de los lineamientos de política en gerencia jurídica, con la oportunidad y periodicidad requerida. 2.Realizar investigaciones jurídicas en derecho público sobre temáticas de mediano y bajo impacto para la ciudad, que le sean asignados y presentar los informes y evaluaciones correspondientes, con criterios de calidad y oportunidad. 3.Elaborar análisis jurisprudencial de las decisiones judiciales de mediano y bajo impacto en temáticas de derecho público, que le sean asignadas y elaborar las fichas correspondientes en los sistemas de información jurídica, para que aporten a la prevención del daño antijurídico. 4.Realizar las actividades para formular y desarrollar las alternativas de Coordinación Jurídica y de Gestión Jurídica Pública para el Distrito Capital, en el marco de la normatividad vigente. 5.Proyectar conceptos jurídicos de mediano impacto, solicitados por las entidades u organismos Distritales y el superior inmediato, con criterios de oportunidad y efectividad. 6.Elaborar anteproyectos de ley, acuerdos, decretos, resoluciones y demás actos administrativos, que se deriven como producto de los estudios e investigaciones jurídicas que se realicen, teniendo en cuenta las normas jurídicas y la jurisprudencia en cada caso. 7.Desempeñar las demás funciones que le asigne el superior inmediato de acuerdo a la naturaleza del cargo. | N6: Estudio: Título profesional en: Derecho; Derecho y Ciencias Sociales; Derecho y Ciencias Políticas; Derecho y Ciencias Humanas; Derecho y Ciencias Administrativas; Derecho Ciencias Políticas y Relaciones Internacionales; Jurisprudencia; Justicia y Derecho; ó Leyess y Jurisprudencia; del núcleo básico de conocimiento en Derecho y afines. Título de postgrado en áreas relacionadas con las funciones del cargo. Tarjeta o matricula profesional en los casos reglamentados por la Ley. | O6: 118-120 RES. 020 de 2019
B7: VACANTE TEMPORAL | D7: 53001416 | E7: DIANA MARIA MORENO VARGAS | F7: PROFESIONAL | G7: PROFESIONAL UNIVERSITARIO | H7: 219 | I7: 18 | J7: 219-18 | K7: DIRECCIÓN DISTRITAL DE POLÍTICA JURÍDICA | L7: realizar el análisis jurídico y jurisprudencial de impacto distrital e incorporar la normatividad, doctrina y jurisprudencia a los sistemas de información jurídica a cargo de la dependencia, adoptando estrategias para la defensa de los intereses públicos y la prevención del daño antijurídico. | M7: 1.Administrar y actualizar la información normativa, doctrinal y jurisprudencial en los sistemas de información jurídica para proporcionar información veraz y oportuna a las entidades, servidores públicos y la ciudadanía en general. 2.Realizar el seguimiento y control a la información contenida en los sistemas de información jurídica, con el fin de adoptar e implementar las acciones de mejora correspondientes, para la defensa de los intereses públicos y la prevención del daño antijurídico. 3.Incorporar documentos jurídicos en los sistemas de información para el ejercicio de la abogacía general del servicio jurídico del Distrito capital con calidad. 4.Realizar informes, estadísticas y análisis de información jurídica contenida en los sistemas de información jurídicos, con calidad, oportunidad y efectividad. 5.Elaborar documentos y boletines jurídicos para que sean publicados en los sistemas de información jurídica con criterios de oportunidad, calidad y efectividad. 6.Proyectar conceptos jurídicos de bajo impacto, solicitados por las entidades u organismos Distritales y asignados por el superior inmediato, de acuerdo a la normatividad vigente. 7.Diseñar la programación y organización de los eventos de orientación y actualización jurídica, para el fortalecimiento del cuerpo de abogados del Distrito capital. 8.Proyectar las respuestas a los requerimientos y/o derechos de petición de alto impacto, que sean asignados a la dependencia, con calidad, oportunidad y efectividad. 9.Desempeñar las demás funciones que le asigne el superior inmediato de acuerdo a la naturaleza del cargo. | N7: Estudio: Título profesional en: Derecho, Derecho y Ciencias Sociales, Derecho y Ciencias Políticas, Derecho y Ciencias Humanas, Derecho y Ciencias Administrativas, Derecho y Ciencias Sociales Derecho, Ciencias Políticas y Relaciones Internacionales, Jurisprudencia, Justicia y Derecho, o Leyes y Jurisprudencia; del núcleo básico de conocimiento en Derecho y afines. Tarjeta o matricula profesional en los casos reglamentados por la Ley. | O7: 165-167 RES. 020 de 2019
B8: VACANTE DEFINITIVA | E8: VACANTE DEFINITIVA | F8: PROFESIONAL | G8: PROFESIONAL UNIVERSITARIO | H8: 219 | I8: 18 | J8: 219-18 | K8: DIRECCIÓN DISTRITAL DE POLÍTICA JURÍDICA | L8: realizar el análisis jurídico y jurisprudencial de impacto distrital e incorporar la normatividad, doctrina y jurisprudencia a los sistemas de información jurídica a cargo de la dependencia, adoptando estrategias para la defensa de los intereses públicos y la prevención del daño antijurídico. | M8: 1.Administrar y actualizar la información normativa, doctrinal y jurisprudencial en los sistemas de información jurídica para proporcionar información veraz y oportuna a las entidades, servidores públicos y la ciudadanía en general. 2.Realizar el seguimiento y control a la información contenida en los sistemas de información jurídica, con el fin de adoptar e implementar las acciones de mejora correspondientes, para la defensa de los intereses públicos y la prevención del daño antijurídico. 3.Incorporar documentos jurídicos en los sistemas de información para el ejercicio de la abogacía general del servicio jurídico del Distrito capital con calidad. 4.Realizar informes, estadísticas y análisis de información jurídica contenida en los sistemas de información jurídicos, con calidad, oportunidad y efectividad. 5.Elaborar documentos y boletines jurídicos para que sean publicados en los sistemas de información jurídica con criterios de oportunidad, calidad y efectividad. 6.Proyectar conceptos jurídicos de bajo impacto, solicitados por las entidades u organismos Distritales y asignados por el superior inmediato, de acuerdo a la normatividad vigente. 7.Diseñar la programación y organización de los eventos de orientación y actualización jurídica, para el fortalecimiento del cuerpo de abogados del Distrito capital. 8.Proyectar las respuestas a los requerimientos y/o derechos de petición de alto impacto, que sean asignados a la dependencia, con calidad, oportunidad y efectividad. 9.Desempeñar las demás funciones que le asigne el superior inmediato de acuerdo a la naturaleza del cargo. | N8: Estudio: Título profesional en: Derecho, Derecho y Ciencias Sociales, Derecho y Ciencias Políticas, Derecho y Ciencias Humanas, Derecho y Ciencias Administrativas, Derecho y Ciencias Sociales Derecho, Ciencias Políticas y Relaciones Internacionales, Jurisprudencia, Justicia y Derecho, o Leyes y Jurisprudencia; del núcleo básico de conocimiento en Derecho y afines. Tarjeta o matricula profesional en los casos reglamentados por la Ley. | O8: 165-167 RES. 020 de 2019
A9: 37625914 | B9: MARY DAYANA SANCHEZ ROJAS | C9: CARRERA ADMINISTRATIVA | D9: 52486713 | E9: CLAUDIA MARCELA CAMARGO CASTRO | F9: PROFESIONAL | G9: PROFESIONAL UNIVERSITARIO | H9: 219 | I9: 13 | J9: 219-13 | K9: DIRECCIÓN DISTRITAL DE POLÍTICA JURÍDICA | L9: proyectar y atender los derechos de petición y solicitudes formuladas, así como realizar análisis de la información contenida en los sistemas de información jurídica, de manera oportuna. | M9: 1.Incorporar los documentos jurídicos en los sistemas de información para la abogacía general del servicio jurídico del Distrito capital, con calidad y oportunidad. 2.Realizar el análisis de información jurídica contenida en los sistemas de información jurídicos, que le sean asignados con criterios de calidad y de veracidad de información. 3.Proyectar las respuestas a los requerimientos y/o derechos de petición de mediano impacto, que sean asignados a la dependencia. 4.Realizar la actualización y/o elaboración de los documentos de relatoría en asuntos de complejidad alta, que permitan la compilación en temáticas afines o de impacto para la ciudad. 5.Desempeñar las demás funciones que le asigne el superior inmediato de acuerdo a la naturaleza del cargo. | N9: Estudio: Título profesional en: Derecho; Derecho y Ciencias Sociales; Derecho y Ciencias Políticas; Derecho y Ciencias Humanas; Derecho y Ciencias Administrativas; Derecho Ciencias Políticas y Relaciones Internacionales; Jurisprudencia; Justicia y Derecho; ó Leyes y Jurisprudencia; del núcleo básico de conocimiento en Derecho y afines. Tarjeta o matricula profesional en los casos reglamentados por la Ley. | O9: 208-209 RES. 020 de 2019
B10: VACANTE TEMPORAL | D10: 86058268 | E10: IAM ALEXANDER OJEDA CARDENAS | F10: PROFESIONAL | G10: PROFESIONAL UNIVERSITARIO | H10: 219 | I10: 13 | J10: 219-13 | K10: DIRECCIÓN DISTRITAL DE POLÍTICA JURÍDICA | L10: realizar la administración de los sistemas de información jurídica, de acuerdo con los lineamientos y parámetros establecidos. | M10: 1.Recopilar y analizar la información registrada en los Sistemas de Información Jurídica en procura de la gestión de la información de manera oportuna y veraz. 2.Generar los informes requeridos, en relación con los Sistemas de Información Jurídica, de manera oportuna. 3.Efectuar las capacitaciones periódicas a los usuarios sobre el manejo de los Sistemas de Información Jurídica de tal forma que les permitan tener las herramientas para la consulta y/o funcionamiento de los mismos. 4.Realizar la orientación sobre el registro de la información y el manejo de los Sistemas de Información Jurídica de manera eficiente y efectiva. 5.Realizar el seguimiento y control técnico de los Sistemas de Información Jurídica, con el fin de identificar los problemas presentados en la operación y solicitar las mejoras correspondientes a la dependencia competente. 6.Establecer alternativas de solución a las problemáticas técnicas presentadas en los Sistemas de Información Jurídica para que contribuya al fortalecimiento de la función pública. 7.Desempeñar las demás funciones que le asigne el superior inmediato de acuerdo a la naturaleza del cargo. | N10: Estudio: Título profesional en: Ingeniería de Sistemas, Ingeniería Telemática, o Ingeniería Informática; del núcleo básico de conocimiento en Ingeniería de Sistemas, Telemática y afines. Tarjeta o matricula profesional en los casos reglamentados por la Ley. | O10: 210-211 RES. 020 de 2019
A11: 22446641 | B11: ROSA ISABEL SIERRA LABORDE | C11: CARRERA ADMINISTRATIVA | D11: 1013608357 | E11: MONICA JULIANA SANMIGUEL ROJAS | F11: PROFESIONAL | G11: PROFESIONAL UNIVERSITARIO | H11: 219 | I11: 3 | J11: 219-3 | K11: DIRECCIÓN DISTRITAL DE POLÍTICA JURÍDICA | L11: proyectar los derechos de petición y solicitudes formuladas a la dependencia, así como realizar el análisis de la información contenida en los sistemas de información jurídica, de manera oportuna y en concordancia con la normatividad vigente. | M11: 1.Proyectar las respuestas a la solicitudes, derechos de petición en asuntos de complejidad baja, acorde con los tiempos estipulados por ley. 2.Realizar el análisis de la información contenida en los sistemas de información jurídicos, que le sean asignados, con criterios eficacia y oportunidad. 3.Realizar la actualización y/o elaboración de los documentos de relatoría en asuntos de complejidad media, con la oportunidad requerida. 4.Efectuar el seguimiento a las jornadas de actualización jurídica del cuerpo de abogados del Distrito Capital y presentar los informes correspondientes para la toma de decisiones por parte del jefe de la dependencia. 5.Desempeñar las demás funciones que le asigne el superior inmediato de acuerdo a la naturaleza del cargo. | N11: Estudio: Título profesional en: Derecho; Derecho y Ciencias Sociales; Derecho y Ciencias Políticas; Derecho y Ciencias Humanas; Derecho y Ciencias Administrativas; Derecho Ciencias Políticas y Relaciones Internacionales; Jurisprudencia; Justicia y Derecho; ó Leyes y Jurisprudencia; del núcleo básico de conocimiento en Derecho y afines. Tarjeta o matricula profesional en los casos reglamentados por la Ley. | O11: 230-232 RES. 020 de 2019
A12: 79894605 | B12: JHON ALEXANDER TIBADUIZA CASTAÑEDA | C12: PROVISIONALIDAD | D12: 1032489040 | E12: LEIDY JOHANNA ALONSO GUTIERREZ | F12: PROFESIONAL | G12: PROFESIONAL UNIVERSITARIO | H12: 219 | I12: 1 | J12: 219-1 | K12: DIRECCIÓN DISTRITAL DE POLÍTICA JURÍDICA | L12: Realizar los procesos de análisis de la información jurídica e incorporarlos en los sistemas jurídicos, así como las actividades requeridas para los eventos de orientación y actualización jurídica al cuerpo de abogados del distrito capital. | M12: 1.Realizar las actividades requeridas para los eventos de orientación y actualización jurídica al cuerpo de Abogados del Distrito Capital, con criterios de eficacia y oportunidad. 2.Realizar la tabulación y el análisis de las encuestas de satisfacción de los eventos de orientación y actualización jurídica al cuerpo de Abogados del Distrito Capital, de manera oportuna. 3.Realizar la publicación de las memorias correspondientes a los eventos y/o la difusión web de las conferencias realizadas, con el fin de mantener actualizada la información. 4.Realizar el análisis de la información jurídica contenida en los sistemas de información jurídicos, que le sean asignados, con criterios de eficacia y oportunidad. 5.Realizar la actualización y/o elaboración de los documentos de relatoría en asuntos de complejidad baja, de manera oportuna. 6.Incorporar los documentos jurídicos en los sistemas de información jurídica, con calidad y oportunidad. 7.Desempeñar las demás funciones que le asigne el superior inmediato de acuerdo a la naturaleza del cargo. | N12: Estudio: Título profesional en: Derecho; Derecho y Ciencias Sociales; Derecho y Ciencias Políticas; Derecho y Ciencias Humanas; Derecho y Ciencias Administrativas; Derecho Ciencias Políticas y Relaciones Internacionales; Jurisprudencia; Justicia y Derecho; ó Leyes y Jurisprudencia; del núcleo básico de conocimiento en Derecho y afines. Tarjeta o matricula profesional en los casos reglamentados por la Ley. | O12: 232-234 RES. 020 de 2019
A13: 30333406 | B13: ALEXANDRA AVILA MARIN | C13: CARRERA ADMINISTRATIVA | D13: 30333406 | E13: ALEXANDRA AVILA MARIN | F13: PROFESIONAL | G13: PROFESIONAL UNIVERSITARIO | H13: 219 | I13: 1 | J13: 219-1 | K13: DIRECCIÓN DISTRITAL DE POLÍTICA JURÍDICA | L13: realizar la incorporación y catalogación de publicaciones y documentos jurídicos en los sistemas de información jurídica, de acuerdo con los parámetros establecidos. | M13: 1.Realizar el trámite de los registros del ISBN y/o ISSN, de acuerdo a los lineamientos técnicos. 2.Proyectar la solicitud de artes gráficas y/o enviar el documento a impresión cuando sea requerido, de conformidad con los requerimientos de las dependencias. 3.Elaborar el plan operativo del Sistema de Información Biblioteca Virtual de Bogotá o el que haga sus veces, de acuerdo con las necesidades y presentar los informes correspondientes dentro de la oportunidad requerida. 4.Establecer y orientar los servicios técnicos y administrativos del Sistema de Información Biblioteca Virtual de Bogotá o el que haga sus veces, para la implementación y desarrollo del mismo. 5.Catalogar, clasificar, analizar y publicar los libros y documentos jurídicos en los Sistemas de Información Jurídica, de acuerdo con los parámetros establecidos. 6.Orientar a los/as funcionarios/as del Distrito Capital en el uso de las fuentes de información y contenidos del Sistema de Información Biblioteca Virtual de Bogotá o el que haga sus veces, para la correcta incorporación de la información, consulta y uso del Sistema. 7.Desempeñar las demás funciones que le asigne el superior inmediato de acuerdo a la naturaleza del cargo. | N13: Estudio: Título profesional en disciplina académica: Ciencias de la Información y la Documentación Bibliotecología y Archivística, Ciencia de la Información – Bibliotecología, Bibliotecología y Archivística, Archivística, Bibliotecología; del núcleo básico de conocimiento en Bibliotecología, otros de Ciencias Sociales y Humanas. Tarjeta o matricula profesional en los casos reglamentados por la Ley. | O13: 232-234 RES. 020 de 2019
A14: 1018499480 | B14: DAYANNA LORENA VELASQUEZ FLOREZ | C14: PROVISIONALIDAD | D14: 22446641 | E14: ROSA ISABEL SIERRA LABORDE | F14: TÉCNICO OPERATIVO | G14: TÉCNICO OPERATIVO | H14: 314 | I14: 15 | J14: 314-15 | K14: DIRECCIÓN DISTRITAL DE POLÍTICA JURÍDICA | L14: asistir en labores técnicas con oportunidad y eficiencia en relación con las actividades misionales de la dependencia, de conformidad con los lineamientos institucionales y la normatividad vigente. | M14: 1.Incorporar la información a los sistemas de información jurídica de la dependencia, verificando la autenticidad de la misma y con la oportunidad requerida. 2.Elaborar dentro de los sistemas de información los vínculos de las normas y las notas de vigencia que le sean solicitados con la oportunidad y precisión requerida. 3.Actualizar la información contenida en los sistemas de información jurídica de la dependencia oportunamente. 4.Revisar la información incorporada al Sistema Régimen Legal de Bogotá – RLB de baja y media complejidad. 5.Analizar y determinar las causas de las no conformidades detectadas en los Sistemas de Información Jurídica y realizar los correctivos necesarios, generando información confiable. 6.Elaborar los documentos que deba presentar en razón a los asuntos de la dependencia, de forma oportuna. 7.Desempeñar las demás funciones que le asigne el superior inmediato de acuerdo a la naturaleza del cargo. | N14: Estudio: Título de formación técnica profesional o tecnológica o terminación y aprobación del pénsum académico de educación superior en formación profesional en: Derecho, Jurídica, Gestión Judicial, Investigación Judicial, Procedimientos Judiciales, Procedimientos Jurídicos, o Proceso Judicial; del núcleo básico de Derecho y afines. | O14: 266-267 RES. 020 de 2019
A15: 1010176886 | B15: JOAN SEBASTIAN FLECHAS ALONSO | C15: CARRERA ADMINISTRATIVA | D15: 1010176886 | E15: JOAN SEBASTIAN FLECHAS ALONSO | F15: TÉCNICO OPERATIVO | G15: TÉCNICO OPERATIVO | H15: 314 | I15: 15 | J15: 314-15 | K15: DIRECCIÓN DISTRITAL DE POLÍTICA JURÍDICA | L15: asistir en labores técnicas con oportunidad y eficiencia en relación con las actividades misionales de la dependencia, de conformidad con los lineamientos institucionales y la normatividad vigente. | M15: 1.Incorporar la información a los sistemas de información jurídica de la dependencia, verificando la autenticidad de la misma y con la oportunidad requerida. 2.Elaborar dentro de los sistemas de información los vínculos de las normas y las notas de vigencia que le sean solicitados con la oportunidad y precisión requerida. 3.Actualizar la información contenida en los sistemas de información jurídica de la dependencia oportunamente. 4.Revisar la información incorporada al Sistema Régimen Legal de Bogotá – RLB de baja y media complejidad. 5.Analizar y determinar las causas de las no conformidades detectadas en los Sistemas de Información Jurídica y realizar los correctivos necesarios, generando información confiable. 6.Elaborar los documentos que deba presentar en razón a los asuntos de la dependencia, de forma oportuna. 7.Desempeñar las demás funciones que le asigne el superior inmediato de acuerdo a la naturaleza del cargo. | N15: Estudio: Título de formación técnica profesional o tecnológica o terminación y aprobación del pénsum académico de educación superior en formación profesional en: Derecho, Jurídica, Gestión Judicial, Investigación Judicial, Procedimientos Judiciales, Procedimientos Jurídicos, o Proceso Judicial; del núcleo básico de Derecho y afines. | O15: 266-267 RES. 020 de 2019

Sheet PLANTA INICIAL
B1: CC | C1: NOMBRE | D1: N | E1: NIVEL | F1: NOMENCLATURA_ADMIN | G1: CÓDIGO | H1: GRADO | J1: DEPENDENCIA | K1: NOMBRAMIENTO
A2: 1 | C2: VACANTE DEFINITIVA | D2: 1 | E2: DIRECTIVO | F2: DIRECTOR TÉCNICO | G2: 9 | H2: 7 | I2: =G2&"-"&H2 -> 9-7 | J2: DIRECCIÓN CORPORATIVA | L2: =C2=P2 -> FALSE | M2: =J2=AH2 -> TRUE | O2: 39546837 | P2: VÁSQUEZ ROJAS ETHEL | Q2: LIBRE NOMBRAMIENTO Y REMOCIÓN | R2: NOMBRAMIENTO ORDINARIO | S2: 42621 | T2: 42622 | U2: MUJER | V2: 53 | X2: VACANTE DEFINITIVA | AB2: OCUPADO | AC2: DIRECTIVO | AD2: DIRECTOR TÉCNICO | AE2: 9 | AF2: 7 | AG2: =AE2&"-"&AF2 -> 9-7 | AH2: DIRECCIÓN CORPORATIVA | AI2: =AG2=I2 -> TRUE
A3: 2 | C3: VACANTE DEFINITIVA | D3: 1 | E3: DIRECTIVO | F3: DIRECTOR TÉCNICO | G3: 9 | H3: 7 | I3: =G3&"-"&H3 -> 9-7 | J3: DIRECCIÓN DISTRITAL DE ASUNTOS DISCIPLINARIOS | K3: LIBRE NOMBRAMIENTO | L3: =C3=P3 -> FALSE | M3: =J3=AH3 -> TRUE | O3: 52394165 | P3: TOBÓN DÍAZ ALEJANDRA | Q3: LIBRE NOMBRAMIENTO Y REMOCIÓN | R3: EN ENCARGO | S3: 42585 | T3: 42404 | U3: MUJER | V3: 43 | W3: ENCARGO | X3: VACANTE DEFINITIVA | Y3: E02 | Z3: 1 | AB3: OCUPADO | AC3: DIRECTIVO | AD3: DIRECTOR TÉCNICO | AE3: 9 | AF3: 7 | AG3: =AE3&"-"&AF3 -> 9-7 | AH3: DIRECCIÓN DISTRITAL DE ASUNTOS DISCIPLINARIOS | AI3: =AG3=I3 -> TRUE
A4: 3 | B4: 28915546 | C4: RODRIGUEZ QUIMBAYO LUZ ELENA | D4: 1 | E4: DIRECTIVO | F4: DIRECTOR TÉCNICO | G4: 9 | H4: 7 | I4: =G4&"-"&H4 -> 9-7 | J4: DIRECCIÓN DISTRITAL DE DEFENSA JUDICIAL Y PREVENCIÓN DEL DAÑO ANTIJURÍDICO | K4: LIBRE NOMBRAMIENTO | L4: =C4=P4 -> TRUE | M4: =J4=AH4 -> TRUE | O4: 28915546 | P4: RODRIGUEZ QUIMBAYO LUZ ELENA | Q4: LIBRE NOMBRAMIENTO Y REMOCIÓN | R4: NOMBRAMIENTO ORDINARIO | S4: 42585 | T4: 42493 | U4: MUJER | V4: 52 | AB4: OCUPADO | AC4: DIRECTIVO | AD4: DIRECTOR TÉCNICO | AE4: 9 | AF4: 7 | AG4: =AE4&"-"&AF4 -> 9-7 | AH4: DIRECCIÓN DISTRITAL DE DEFENSA JUDICIAL Y PREVENCIÓN DEL DAÑO ANTIJURÍDICO | AI4: =AG4=I4 -> TRUE
A5: 4 | C5: VACANTE DEFINITIVA | D5: 1 | E5: DIRECTIVO | F5: DIRECTOR TÉCNICO | G5: 9 | H5: 7 | I5: =G5&"-"&H5 -> 9-7 | J5: DIRECCIÓN DISTRITAL DE DOCTRINA JURÍDICA | L5: =C5=P5 -> FALSE | M5: =J5=AH5 -> TRUE | O5: 51743499 | P5: ANA LUCY CASTRO CASTRO | Q5: LIBRE NOMBRAMIENTO Y REMOCIÓN | R5: NOMBRAMIENTO ORDINARIO | S5: 42607 | T5: 42461 | U5: MUJER | V5: 58 | AB5: OCUPADO | AC5: DIRECTIVO | AD5: DIRECTOR TÉCNICO | AE5: 9 | AF5: 7 | AG5: =AE5&"-"&AF5 -> 9-7 | AH5: DIRECCIÓN DISTRITAL DE DOCTRINA JURÍDICA | AI5: =AG5=I5 -> TRUE
A6: 5 | B6: 35521959 | C6: MARTÍNEZ SIERRA GLORIA EDITH | D6: 1 | E6: DIRECTIVO | F6: DIRECTOR TÉCNICO | G6: 9 | H6: 7 | I6: =G6&"-"&H6 -> 9-7 | J6: DIRECCIÓN DISTRITAL DE POLÍTICA E INFORMÁTICA JURÍDICA | K6: LIBRE NOMBRAMIENTO | L6: =C6=P6 -> TRUE | M6: =J6=AH6 -> TRUE | O6: 35521959 | P6: MARTÍNEZ SIERRA GLORIA EDITH | Q6: LIBRE NOMBRAMIENTO Y REMOCIÓN | R6: NOMBRAMIENTO ORDINARIO | S6: 42585 | T6: 42461 | U6: MUJER | V6: 53 | AB6: OCUPADO | AC6: DIRECTIVO | AD6: DIRECTOR TÉCNICO | AE6: 9 | AF6: 7 | AG6: =AE6&"-"&AF6 -> 9-7 | AH6: DIRECCIÓN DISTRITAL DE POLÍTICA E INFORMÁTICA JURÍDICA | AI6: =AG6=I6 -> TRUE
A7: 6 | B7: 39742375 | C7: ROBAYO ALFONSO ANDREA | D7: 1 | E7: DIRECTIVO | F7: DIRECTOR TÉCNICO | G7: 9 | H7: 7 | I7: =G7&"-"&H7 -> 9-7 | J7: DIRECCIÓN DISTRITAL DE INSPECCIÓN VIGILANCIA Y CONTROL DE LAS ENTIDADES SIN ÁNIMO DE LUCRO | K7: LIBRE NOMBRAMIENTO | L7: =C7=P7 -> TRUE | M7: =J7=AH7 -> TRUE | O7: 39742375 | P7: ROBAYO ALFONSO ANDREA | Q7: LIBRE NOMBRAMIENTO Y REMOCIÓN | R7: NOMBRAMIENTO ORDINARIO | S7: 42585 | T7: 42523 | U7: MUJER | V7: 45 | AB7: OCUPADO | AC7: DIRECTIVO | AD7: DIRECTOR TÉCNICO | AE7: 9 | AF7: 7 | AG7: =AE7&"-"&AF7 -> 9-7 | AH7: DIRECCIÓN DISTRITAL DE INSPECCIÓN VIGILANCIA Y CONTROL DE LAS ENTIDADES SIN ÁNIMO DE LUCRO | AI7: =AG7=I7 -> TRUE
A8: 7 | C8: VACANTE DEFINITIVA | D8: 1 | E8: DIRECTIVO | F8: JEFE DE OFICINA | G8: 6 | H8: 6 | I8: =G8&"-"&H8 -> 6-6 | J8: OFICINA DE CONTROL INTERNO | L8: =C8=P8 -> TRUE | M8: =J8=AH8 -> TRUE | P8: VACANTE DEFINITIVA | R8: VACANTE DEFINITIVA | X8: VACANTE DEFINITIVA | AB8: VACANTE DEFINITIVA | AC8: DIRECTIVO | AD8: JEFE DE OFICINA | AE8: 6 | AF8: 6 | AG8: =AE8&"-"&AF8 -> 6-6 | AH8: OFICINA DE CONTROL INTERNO | AI8: =AG8=I8 -> TRUE
A9: 8 | B9: 51740995 | C9: HERNANDEZ CORZO DALILA ASTRID | D9: 1 | E9: DIRECTIVO | F9: SECRETARIA JURIDICA | G9: 20 | H9: 9 | I9: =G9&"-"&H9 -> 20-9 | J9: DESPACHO | K9: LIBRE NOMBRAMIENTO | L9: =C9=P9 -> TRUE | M9: =J9=AH9 -> TRUE | O9: 51740995 | P9: HERNANDEZ CORZO DALILA ASTRID | Q9: LIBRE NOMBRAMIENTO Y REMOCIÓN | R9: NOMBRAMIENTO ORDINARIO | S9: 42585 | T9: 42394 | U9: MUJER | V9: 57 | AB9: OCUPADO | AC9: DIRECTIVO | AD9: SECRETARIA JURIDICA | AE9: 20 | AF9: 9 | AG9: =AE9&"-"&AF9 -> 20-9 | AH9: DESPACHO | AI9: =AG9=I9 -> TRUE
A10: 9 | B10: 79543049 | C10: BURGOS DURANGO WILLIAM ANTONIO | D10: 1 | E10: DIRECTIVO | F10: SUBSECRETARIO | G10: 45 | H10: 8 | I10: =G10&"-"&H10 -> 45-8 | J10: SUBSECRETARÍA JURÍDICA | K10: LIBRE NOMBRAMIENTO | L10: =C10=P10 -> TRUE | M10: =J10=AH10 -> TRUE | O10: 79543049 | P10: BURGOS DURANGO WILLIAM ANTONIO | Q10: LIBRE NOMBRAMIENTO Y REMOCIÓN | R10: NOMBRAMIENTO ORDINARIO | S10: 42585 | T10: 42403 | U10: HOMBRE | V10: 51 | AB10: OCUPADO | AC10: DIRECTIVO | AD10: SUBSECRETARIO | AE10: 45 | AF10: 8 | AG10: =AE10&"-"&AF10 -> 45-8 | AH10: SUBSECRETARÍA JURÍDICA | AI10: =AG10=I10 -> TRUE
A11: 10 | B11: 1085262099 | C11: BURBANO SÁNCHEZ MARÍA ANGÉLICA | D11: 2 | E11: ASESOR | F11: ASESOR | G11: 105 | H11: 5 | I11: =G11&"-"&H11 -> 105-5 | J11: DESPACHO | K11: LIBRE NOMBRAMIENTO | L11: =C11=P11 -> FALSE | M11: =J11=AH11 -> TRUE | O11: 79317479 | P11: CORDOBA DELGADO JOSE IGNACIO | Q11: LIBRE NOMBRAMIENTO Y REMOCIÓN | R11: NOMBRAMIENTO ORDINARIO | S11: 42632 | T11: 42632 | U11: HOMBRE | V11: 60 | X11: VACANTE DEFINITIVA | AB11: OCUPADO | AC11: ASESOR | AD11: ASESOR | AE11: 105 | AF11: 5 | AG11: =AE11&"-"&AF11 -> 105-5 | AH11: DESPACHO | AI11: =AG11=I11 -> TRUE
A12: 11 | B12: 80040965 | C12: CUELLAR TRUJILLO PEDRO ANDRÉS | D12: 2 | E12: ASESOR | F12: ASESOR | G12: 105 | H12: 5 | I12: =G12&"-"&H12 -> 105-5 | J12: DESPACHO | K12: LIBRE NOMBRAMIENTO | L12: =C12=P12 -> TRUE | M12: =J12=AH12 -> TRUE | O12: 80040965 | P12: CUELLAR TRUJILLO PEDRO ANDRÉS | Q12: LIBRE NOMBRAMIENTO Y REMOCIÓN | R12: NOMBRAMIENTO ORDINARIO | S12: 42585 | T12: 42401 | U12: HOMBRE | V12: 39 | AB12: OCUPADO | AC12: ASESOR | AD12: ASESOR | AE12: 105 | AF12: 5 | AG12: =AE12&"-"&AF12 -> 105-5 | AH12: DESPACHO | AI12: =AG12=I12 -> TRUE
A13: 12 | B13: 72291125 | C13: ESPINOSA OTERO ANDRES MAURICIO | D13: 2 | E13: ASESOR | F13: ASESOR | G13: 105 | H13: 5 | I13: =G13&"-"&H13 -> 105-5 | J13: DESPACHO | K13: LIBRE NOMBRAMIENTO | L13: =C13=P13 -> TRUE | M13: =J13=AH13 -> TRUE | O13: 72291125 | P13: ESPINOSA OTERO ANDRES MAURICIO | Q13: LIBRE NOMBRAMIENTO Y REMOCIÓN | R13: NOMBRAMIENTO ORDINARIO | S13: 42585 | T13: 42468 | U13: HOMBRE | V13: 38 | AB13: OCUPADO | AC13: ASESOR | AD13: ASESOR | AE13: 105 | AF13: 5 | AG13: =AE13&"-"&AF13 -> 105-5 | AH13: DESPACHO | AI13: =AG13=I13 -> TRUE
A14: 13 | B14: 52233911 | C14: RODRÍGUEZ BARRERA NOHORA PATRICIA | D14: 2 | E14: ASESOR | F14: ASESOR | G14: 105 | H14: 5 | I14: =G14&"-"&H14 -> 105-5 | J14: DESPACHO | K14: LIBRE NOMBRAMIENTO | L14: =C14=P14 -> TRUE | M14: =J14=AH14 -> TRUE | O14: 52233911 | P14: RODRÍGUEZ BARRERA NOHORA PATRICIA | Q14: LIBRE NOMBRAMIENTO Y REMOCIÓN | R14: NOMBRAMIENTO ORDINARIO | S14: 42585 | T14: 35900 | U14: MUJER | V14: 44 | AB14: OCUPADO | AC14: ASESOR | AD14: ASESOR | AE14: 105 | AF14: 5 | AG14: =AE14&"-"&AF14 -> 105-5 | AH14: DESPACHO | AI14: =AG14=I14 -> TRUE
A15: 14 | B15: 52394165 | C15: TOBÓN DÍAZ ALEJANDRA | D15: 2 | E15: ASESOR | F15: ASESOR | G15: 105 | H15: 5 | I15: =G15&"-"&H15 -> 105-5 | J15: DESPACHO | K15: LIBRE NOMBRAMIENTO | L15: =C15=P15 -> FALSE | M15: =J15=AH15 -> TRUE | P15: VACANTE TEMPORAL | R15: VACANTE TEMPORAL | X15: TOBÓN DÍAZ ALEJANDRA | Y15: E02 | Z15: VT | AB15: OCUPADO | AC15: ASESOR | AD15: ASESOR | AE15: 105 | AF15: 5 | AG15: =AE15&"-"&AF15 -> 105-5 | AH15: DESPACHO | AI15: =AG15=I15 -> TRUE
A16: 15 | C16: VACANTE DEFINITIVA | D16: 2 | E16: ASESOR | F16: JEFE DE OFICINA | G16: 115 | H16: 6 | I16: =G16&"-"&H16 -> 115-6 | J16: OFICINA ASESORA DE PLANEACIÓN | L16: =C16=P16 -> TRUE | M16: =J16=AH16 -> TRUE | P16: VACANTE DEFINITIVA | R16: VACANTE DEFINITIVA | X16: VACANTE DEFINITIVA | AB16: VACANTE DEFINITIVA | AC16: ASESOR | AD16: JEFE DE OFICINA | AE16: 115 | AF16: 6 | AG16: =AE16&"-"&AF16 -> 115-6 | AH16: OFICINA ASESORA DE PLANEACIÓN | AI16: =AG16=I16 -> TRUE
A17: 16 | C17: VACANTE DEFINITIVA | D17: 2 | E17: ASESOR | F17: JEFE DE OFICINA | G17: 115 | H17: 6 | I17: =G17&"-"&H17 -> 115-6 | J17: OFICINA DE TECNOLOGÍA DE LA INFORMACIÓN, SISTEMAS Y COMUNICACIONES | L17: =C17=P17 -> FALSE | M17: =J17=AH17 -> TRUE | O17: 19498970 | P17: OJEDA MONCAYO DIEGO EMILIO | Q17: LIBRE NOMBRAMIENTO Y REMOCIÓN | R17: NOMBRAMIENTO ORDINARIO | S17: 42622 | T17: 42622 | U17: HOMBRE | V17: 59 | X17: VACANTE DEFINITIVA | AB17: OCUPADO | AC17: ASESOR | AD17: JEFE DE OFICINA | AE17: 115 | AF17: 6 | AG17: =AE17&"-"&AF17 -> 115-6 | AH17: OFICINA DE TECNOLOGÍA DE LA INFORMACIÓN, SISTEMAS Y COMUNICACIONES | AI17: =AG17=I17 -> TRUE
A18: 17 | B18: 79299847 | C18: MONTOYA MALDONADO JESÚS MARÍA | D18: 3 | E18: PROFESIONAL | F18: PROFESIONAL ESPECIALIZADO | G18: 222 | H18: 27 | I18: =G18&"-"&H18 -> 222-27 | J18: DIRECCIÓN CORPORATIVA | K18: CARRERA ADMINISTRATIVA | L18: =C18=P18 -> TRUE | M18: =J18=AH18 -> TRUE | O18: 79299847 | P18: MONTOYA MALDONADO JESÚS MARÍA | Q18: CARRERA ADMINISTRATIVA | R18: CARRERA ADMINISTRATIVA | S18: 42585 | T18: 33724 | U18: HOMBRE | V18: 60 | AB18: OCUPADO | AC18: PROFESIONAL | AD18: PROFESIONAL ESPECIALIZADO | AE18: 222 | AF18: 27 | AG18: =AE18&"-"&AF18 -> 222-27 | AH18: DIRECCIÓN CORPORATIVA | AI18: =AG18=I18 -> TRUE
A19: 18 | C19: VACANTE DEFINITIVA | D19: 3 | E19: PROFESIONAL | F19: PROFESIONAL ESPECIALIZADO | G19: 222 | H19: 27 | I19: =G19&"-"&H19 -> 222-27 | J19: DIRECCIÓN CORPORATIVA | L19: =C19=P19 -> TRUE | M19: =J19=AH19 -> TRUE | P19: VACANTE DEFINITIVA | R19: VACANTE DEFINITIVA | X19: VACANTE DEFINITIVA | AB19: VACANTE DEFINITIVA | AC19: PROFESIONAL | AD19: PROFESIONAL ESPECIALIZADO | AE19: 222 | AF19: 27 | AG19: =AE19&"-"&AF19 -> 222-27 | AH19: DIRECCIÓN CORPORATIVA | AI19: =AG19=I19 -> TRUE
A20: 19 | B20: 52236487 | C20: MORENO GUERRERO DEYSI YANIRA | D20: 3 | E20: PROFESIONAL | F20: PROFESIONAL ESPECIALIZADO | G20: 222 | H20: 27 | I20: =G20&"-"&H20 -> 222-27 | J20: DIRECCIÓN DISTRITAL DE ASUNTOS DISCIPLINARIOS | K20: CARRERA ADMINISTRATIVA | L20: =C20=P20 -> TRUE | M20: =J20=AH20 -> TRUE | O20: 52236487 | P20: MORENO GUERRERO DEYSI YANIRA | Q20: CARRERA ADMINISTRATIVA | R20: CARRERA ADMINISTRATIVA | S20: 42585 | T20: 38093 | U20: MUJER | V20: 44 | AB20: OCUPADO | AC20: PROFESIONAL | AD20: PROFESIONAL ESPECIALIZADO | AE20: 222 | AF20: 27 | AG20: =AE20&"-"&AF20 -> 222-27 | AH20: DIRECCIÓN DISTRITAL DE ASUNTOS DISCIPLINARIOS | AI20: =AG20=I20 -> TRUE
A21: 20 | C21: VACANTE DEFINITIVA | D21: 3 | E21: PROFESIONAL | F21: PROFESIONAL ESPECIALIZADO | G21: 222 | H21: 27 | I21: =G21&"-"&H21 -> 222-27 | J21: SUBSECRETARÍA JURÍDICA | L21: =C21=P21 -> TRUE | M21: =J21=AH21 -> TRUE | P21: VACANTE DEFINITIVA | R21: VACANTE DEFINITIVA | X21: VACANTE DEFINITIVA | AB21: VACANTE DEFINITIVA | AC21: PROFESIONAL | AD21: PROFESIONAL ESPECIALIZADO | AE21: 222 | AF21: 27 | AG21: =AE21&"-"&AF21 -> 222-27 | AH21: SUBSECRETARÍA JURÍDICA | AI21: =AG21=I21 -> TRUE
A22: 21 | C22: VACANTE DEFINITIVA | D22: 3 | E22: PROFESIONAL | F22: PROFESIONAL ESPECIALIZADO | G22: 222 | H22: 27 | I22: =G22&"-"&H22 -> 222-27 | J22: SUBSECRETARÍA JURÍDICA | L22: =C22=P22 -> TRUE | M22: =J22=AH22 -> TRUE | P22: VACANTE DEFINITIVA | R22: VACANTE DEFINITIVA | X22: VACANTE DEFINITIVA | AB22: VACANTE DEFINITIVA | AC22: PROFESIONAL | AD22: PROFESIONAL ESPECIALIZADO | AE22: 222 | AF22: 27 | AG22: =AE22&"-"&AF22 -> 222-27 | AH22: SUBSECRETARÍA JURÍDICA | AI22: =AG22=I22 -> TRUE
A23: 22 | C23: VACANTE DEFINITIVA | D23: 3 | E23: PROFESIONAL | F23: PROFESIONAL ESPECIALIZADO | G23: 222 | H23: 27 | I23: =G23&"-"&H23 -> 222-27 | J23: SUBSECRETARÍA JURÍDICA | L23: =C23=P23 -> TRUE | M23: =J23=AH23 -> TRUE | P23: VACANTE DEFINITIVA | R23: VACANTE DEFINITIVA | X23: VACANTE DEFINITIVA | AB23: VACANTE DEFINITIVA | AC23: PROFESIONAL | AD23: PROFESIONAL ESPECIALIZADO | AE23: 222 | AF23: 27 | AG23: =AE23&"-"&AF23 -> 222-27 | AH23: SUBSECRETARÍA JURÍDICA | AI23: =AG23=I23 -> TRUE
A24: 23 | B24: 51798311 | C24: AMAYA SALAZAR MARTHA YOLANDA | D24: 3 | E24: PROFESIONAL | F24: PROFESIONAL ESPECIALIZADO | G24: 222 | H24: 27 | I24: =G24&"-"&H24 -> 222-27 | J24: DIRECCIÓN DISTRITAL DE DEFENSA JUDICIAL Y PREVENCIÓN DEL DAÑO ANTIJURÍDICO | K24: CARRERA ADMINISTRATIVA | L24: =C24=P24 -> TRUE | M24: =J24=AH24 -> TRUE | O24: 51798311 | P24: AMAYA SALAZAR MARTHA YOLANDA | Q24: CARRERA ADMINISTRATIVA | R24: CARRERA ADMINISTRATIVA | S24: 42585 | T24: 34457 | U24: MUJER | V24: 57 | AB24: OCUPADO | AC24: PROFESIONAL | AD24: PROFESIONAL ESPECIALIZADO | AE24: 222 | AF24: 27 | AG24: =AE24&"-"&AF24 -> 222-27 | AH24: DIRECCIÓN DISTRITAL DE DEFENSA JUDICIAL Y PREVENCIÓN DEL DAÑO ANTIJURÍDICO | AI24: =AG24=I24 -> TRUE
A25: 24 | B25: 79153811 | C25: CADENA ROJAS ERNESTO | D25: 3 | E25: PROFESIONAL | F25: PROFESIONAL ESPECIALIZADO | G25: 222 | H25: 27 | I25: =G25&"-"&H25 -> 222-27 | J25: DIRECCIÓN DISTRITAL DE DEFENSA JUDICIAL Y PREVENCIÓN DEL DAÑO ANTIJURÍDICO | K25: CARRERA ADMINISTRATIVA | L25: =C25=P25 -> TRUE | M25: =J25=AH25 -> TRUE | O25: 79153811 | P25: CADENA ROJAS ERNESTO | Q25: CARRERA ADMINISTRATIVA | R25: CARRERA ADMINISTRATIVA | S25: 42585 | T25: 34256 | U25: HOMBRE | V25: 60 | AB25: OCUPADO | AC25: PROFESIONAL | AD25: PROFESIONAL ESPECIALIZADO | AE25: 222 | AF25: 27 | AG25: =AE25&"-"&AF25 -> 222-27 | AH25: DIRECCIÓN DISTRITAL DE DEFENSA JUDICIAL Y PREVENCIÓN DEL DAÑO ANTIJURÍDICO | AI25: =AG25=I25 -> TRUE
A26: 25 | B26: 51569861 | C26: DIAGO CASASBUENAS GLORIA MAGDALENA | D26: 3 | E26: PROFESIONAL | F26: PROFESIONAL ESPECIALIZADO | G26: 222 | H26: 27 | I26: =G26&"-"&H26 -> 222-27 | J26: DIRECCIÓN DISTRITAL DE DEFENSA JUDICIAL Y PREVENCIÓN DEL DAÑO ANTIJURÍDICO | K26: CARRERA ADMINISTRATIVA | L26: =C26=P26 -> TRUE | M26: =J26=AH26 -> TRUE | O26: 51569861 | P26: DIAGO CASASBUENAS GLORIA MAGDALENA | Q26: CARRERA ADMINISTRATIVA | R26: CARRERA ADMINISTRATIVA | S26: 42585 | T26: 34684 | U26: MUJER | V26: 63 | AB26: OCUPADO | AC26: PROFESIONAL | AD26: PROFESIONAL ESPECIALIZADO | AE26: 222 | AF26: 27 | AG26: =AE26&"-"&AF26 -> 222-27 | AH26: DIRECCIÓN DISTRITAL DE DEFENSA JUDICIAL Y PREVENCIÓN DEL DAÑO ANTIJURÍDICO | AI26: =AG26=I26 -> TRUE
A27: 26 | C27: VACANTE DEFINITIVA | D27: 3 | E27: PROFESIONAL | F27: PROFESIONAL ESPECIALIZADO | G27: 222 | H27: 27 | I27: =G27&"-"&H27 -> 222-27 | J27: DIRECCIÓN DISTRITAL DE DEFENSA JUDICIAL Y PREVENCIÓN DEL DAÑO ANTIJURÍDICO | L27: =C27=P27 -> TRUE | M27: =J27=AH27 -> TRUE | P27: VACANTE DEFINITIVA | R27: VACANTE DEFINITIVA | X27: VACANTE DEFINITIVA | AB27: VACANTE DEFINITIVA | AC27: PROFESIONAL | AD27: PROFESIONAL ESPECIALIZADO | AE27: 222 | AF27: 27 | AG27: =AE27&"-"&AF27 -> 222-27 | AH27: DIRECCIÓN DISTRITAL DE DEFENSA JUDICIAL Y PREVENCIÓN DEL DAÑO ANTIJURÍDICO | AI27: =AG27=I27 -> TRUE
A28: 27 | C28: VACANTE DEFINITIVA | D28: 3 | E28: PROFESIONAL | F28: PROFESIONAL ESPECIALIZADO | G28: 222 | H28: 27 | I28: =G28&"-"&H28 -> 222-27 | J28: DIRECCIÓN DISTRITAL DE DEFENSA JUDICIAL Y PREVENCIÓN DEL DAÑO ANTIJURÍDICO | L28: =C28=P28 -> TRUE | M28: =J28=AH28 -> TRUE | P28: VACANTE DEFINITIVA | R28: VACANTE DEFINITIVA | X28: VACANTE DEFINITIVA | AB28: VACANTE DEFINITIVA | AC28: PROFESIONAL | AD28: PROFESIONAL ESPECIALIZADO | AE28: 222 | AF28: 27 | AG28: =AE28&"-"&AF28 -> 222-27 | AH28: DIRECCIÓN DISTRITAL DE DEFENSA JUDICIAL Y PREVENCIÓN DEL DAÑO ANTIJURÍDICO | AI28: =AG28=I28 -> TRUE
A29: 28 | C29: VACANTE DEFINITIVA | D29: 3 | E29: PROFESIONAL | F29: PROFESIONAL ESPECIALIZADO | G29: 222 | H29: 27 | I29: =G29&"-"&H29 -> 222-27 | J29: DIRECCIÓN DISTRITAL DE DEFENSA JUDICIAL Y PREVENCIÓN DEL DAÑO ANTIJURÍDICO | L29: =C29=P29 -> TRUE | M29: =J29=AH29 -> TRUE | P29: VACANTE DEFINITIVA | R29: VACANTE DEFINITIVA | X29: VACANTE DEFINITIVA | AB29: VACANTE DEFINITIVA | AC29: PROFESIONAL | AD29: PROFESIONAL ESPECIALIZADO | AE29: 222 | AF29: 27 | AG29: =AE29&"-"&AF29 -> 222-27 | AH29: DIRECCIÓN DISTRITAL DE DEFENSA JUDICIAL Y PREVENCIÓN DEL DAÑO ANTIJURÍDICO | AI29: =AG29=I29 -> TRUE
A30: 29 | C30: VACANTE DEFINITIVA | D30: 3 | E30: PROFESIONAL | F30: PROFESIONAL ESPECIALIZADO | G30: 222 | H30: 27 | I30: =G30&"-"&H30 -> 222-27 | J30: DIRECCIÓN DISTRITAL DE DEFENSA JUDICIAL Y PREVENCIÓN DEL DAÑO ANTIJURÍDICO | L30: =C30=P30 -> TRUE | M30: =J30=AH30 -> TRUE | P30: VACANTE DEFINITIVA | R30: VACANTE DEFINITIVA | X30: VACANTE DEFINITIVA | AB30: VACANTE DEFINITIVA | AC30: PROFESIONAL | AD30: PROFESIONAL ESPECIALIZADO | AE30: 222 | AF30: 27 | AG30: =AE30&"-"&AF30 -> 222-27 | AH30: DIRECCIÓN DISTRITAL DE DEFENSA JUDICIAL Y PREVENCIÓN DEL DAÑO ANTIJURÍDICO | AI30: =AG30=I30 -> TRUE
A31: 30 | C31: VACANTE DEFINITIVA | D31: 3 | E31: PROFESIONAL | F31: PROFESIONAL ESPECIALIZADO | G31: 222 | H31: 27 | I31: =G31&"-"&H31 -> 222-27 | J31: DIRECCIÓN DISTRITAL DE DEFENSA JUDICIAL Y PREVENCIÓN DEL DAÑO ANTIJURÍDICO | L31: =C31=P31 -> TRUE | M31: =J31=AH31 -> TRUE | P31: VACANTE DEFINITIVA | R31: VACANTE DEFINITIVA | X31: VACANTE DEFINITIVA | AB31: VACANTE DEFINITIVA | AC31: PROFESIONAL | AD31: PROFESIONAL ESPECIALIZADO | AE31: 222 | AF31: 27 | AG31: =AE31&"-"&AF31 -> 222-27 | AH31: DIRECCIÓN DISTRITAL DE DEFENSA JUDICIAL Y PREVENCIÓN DEL DAÑO ANTIJURÍDICO | AI31: =AG31=I31 -> TRUE
A32: 31 | C32: VACANTE DEFINITIVA | D32: 3 | E32: PROFESIONAL | F32: PROFESIONAL ESPECIALIZADO | G32: 222 | H32: 27 | I32: =G32&"-"&H32 -> 222-27 | J32: DIRECCIÓN DISTRITAL DE DEFENSA JUDICIAL Y PREVENCIÓN DEL DAÑO ANTIJURÍDICO | L32: =C32=P32 -> TRUE | M32: =J32=AH32 -> TRUE | P32: VACANTE DEFINITIVA | R32: VACANTE DEFINITIVA | X32: VACANTE DEFINITIVA | AB32: VACANTE DEFINITIVA | AC32: PROFESIONAL | AD32: PROFESIONAL ESPECIALIZADO | AE32: 222 | AF32: 27 | AG32: =AE32&"-"&AF32 -> 222-27 | AH32: DIRECCIÓN DISTRITAL DE DEFENSA JUDICIAL Y PREVENCIÓN DEL DAÑO ANTIJURÍDICO | AI32: =AG32=I32 -> TRUE
A33: 32 | B33: 52363895 | C33: HERNANDEZ LIBREROS ELVIRA LILIANA | D33: 3 | E33: PROFESIONAL | F33: PROFESIONAL ESPECIALIZADO | G33: 222 | H33: 27 | I33: =G33&"-"&H33 -> 222-27 | J33: DIRECCIÓN DISTRITAL DE DOCTRINA JURÍDICA | K33: CARRERA ADMINISTRATIVA | L33: =C33=P33 -> TRUE | M33: =J33=AH33 -> TRUE | O33: 52363895 | P33: HERNANDEZ LIBREROS ELVIRA LILIANA | Q33: CARRERA ADMINISTRATIVA | R33: CARRERA ADMINISTRATIVA | S33: 42585 | T33: 37994 | U33: MUJER | V33: 46 | AB33: OCUPADO | AC33: PROFESIONAL | AD33: PROFESIONAL ESPECIALIZADO | AE33: 222 | AF33: 27 | AG33: =AE33&"-"&AF33 -> 222-27 | AH33: DIRECCIÓN DISTRITAL DE DOCTRINA JURÍDICA | AI33: =AG33=I33 -> TRUE
A34: 33 | B34: 52009661 | C34: TIBAMOSCA VILLAMARÍN SANDRA YANETH | D34: 3 | E34: PROFESIONAL | F34: PROFESIONAL ESPECIALIZADO | G34: 222 | H34: 27 | I34: =G34&"-"&H34 -> 222-27 | J34: DIRECCIÓN DISTRITAL DE DOCTRINA JURÍDICA | K34: CARRERA ADMINISTRATIVA | L34: =C34=P34 -> TRUE | M34: =J34=AH34 -> TRUE | O34: 52009661 | P34: TIBAMOSCA VILLAMARÍN SANDRA YANETH | Q34: CARRERA ADMINISTRATIVA | R34: EN COMISIÓN EN EMPLEO DE L.N.R. O DE PERIODO | S34: 42585 | T34: 35387 | U34: MUJER | V34: 50 | W34: COMISIÒN | AA34: CM | AB34: OCUPADO | AC34: PROFESIONAL | AD34: PROFESIONAL ESPECIALIZADO | AE34: 222 | AF34: 27 | AG34: =AE34&"-"&AF34 -> 222-27 | AH34: DIRECCIÓN DISTRITAL DE DOCTRINA JURÍDICA | AI34: =AG34=I34 -> TRUE
A35: 34 | C35: VACANTE DEFINITIVA | D35: 3 | E35: PROFESIONAL | F35: PROFESIONAL ESPECIALIZADO | G35: 222 | H35: 27 | I35: =G35&"-"&H35 -> 222-27 | J35: DIRECCIÓN DISTRITAL DE DOCTRINA JURÍDICA | L35: =C35=P35 -> TRUE | M35: =J35=AH35 -> TRUE | P35: VACANTE DEFINITIVA | R35: VACANTE DEFINITIVA | X35: VACANTE DEFINITIVA | AB35: VACANTE DEFINITIVA | AC35: PROFESIONAL | AD35: PROFESIONAL ESPECIALIZADO | AE35: 222 | AF35: 27 | AG35: =AE35&"-"&AF35 -> 222-27 | AH35: DIRECCIÓN DISTRITAL DE DOCTRINA JURÍDICA | AI35: =AG35=I35 -> TRUE
A36: 35 | B36: 24179106 | C36: ROJAS SUÁREZ ZULMA | D36: 3 | E36: PROFESIONAL | F36: PROFESIONAL ESPECIALIZADO | G36: 222 | H36: 27 | I36: =G36&"-"&H36 -> 222-27 | J36: DIRECCIÓN DISTRITAL DE POLÍTICA E INFORMÁTICA JURÍDICA | K36: CARRERA ADMINISTRATIVA | L36: =C36=P36 -> TRUE | M36: =J36=AH36 -> TRUE | O36: 24179106 | P36: ROJAS SUÁREZ ZULMA | Q36: CARRERA ADMINISTRATIVA | R36: CARRERA ADMINISTRATIVA | S36: 42585 | T36: 38316 | U36: MUJER | V36: 45 | AB36: OCUPADO | AC36: PROFESIONAL | AD36: PROFESIONAL ESPECIALIZADO | AE36: 222 | AF36: 27 | AG36: =AE36&"-"&AF36 -> 222-27 | AH36: DIRECCIÓN DISTRITAL DE POLÍTICA E INFORMÁTICA JURÍDICA | AI36: =AG36=I36 -> TRUE
A37: 36 | C37: VACANTE DEFINITIVA | D37: 3 | E37: PROFESIONAL | F37: PROFESIONAL ESPECIALIZADO | G37: 222 | H37: 27 | I37: =G37&"-"&H37 -> 222-27 | J37: DIRECCIÓN DISTRITAL DE POLÍTICA E INFORMÁTICA JURÍDICA | L37: =C37=P37 -> TRUE | M37: =J37=AH37 -> TRUE | P37: VACANTE DEFINITIVA | R37: VACANTE DEFINITIVA | X37: VACANTE DEFINITIVA | AB37: VACANTE DEFINITIVA | AC37: PROFESIONAL | AD37: PROFESIONAL ESPECIALIZADO | AE37: 222 | AF37: 27 | AG37: =AE37&"-"&AF37 -> 222-27 | AH37: DIRECCIÓN DISTRITAL DE POLÍTICA E INFORMÁTICA JURÍDICA | AI37: =AG37=I37 -> TRUE
A38: 37 | B38: 19347862 | C38: HERNANDEZ ALBARRACÍN JORGE ELIÉCER | D38: 3 | E38: PROFESIONAL | F38: PROFESIONAL ESPECIALIZADO | G38: 222 | H38: 27 | I38: =G38&"-"&H38 -> 222-27 | J38: DIRECCIÓN DISTRITAL DE INSPECCIÓN VIGILANCIA Y CONTROL DE LAS ENTIDADES SIN ÁNIMO DE LUCRO | K38: CARRERA ADMINISTRATIVA | L38: =C38=P38 -> TRUE | M38: =J38=AH38 -> TRUE | O38: 19347862 | P38: HERNANDEZ ALBARRACÍN JORGE ELIÉCER | Q38: CARRERA ADMINISTRATIVA | R38: CARRERA ADMINISTRATIVA | S38: 42585 | T38: 34464 | U38: HOMBRE | V38: 65 | AB38: OCUPADO | AC38: PROFESIONAL | AD38: PROFESIONAL ESPECIALIZADO | AE38: 222 | AF38: 27 | AG38: =AE38&"-"&AF38 -> 222-27 | AH38: DIRECCIÓN DISTRITAL DE INSPECCIÓN VIGILANCIA Y CONTROL DE LAS ENTIDADES SIN ÁNIMO DE LUCRO | AI38: =AG38=I38 -> TRUE
A39: 38 | C39: VACANTE DEFINITIVA | D39: 3 | E39: PROFESIONAL | F39: PROFESIONAL ESPECIALIZADO | G39: 222 | H39: 27 | I39: =G39&"-"&H39 -> 222-27 | J39: DIRECCIÓN DISTRITAL DE INSPECCIÓN VIGILANCIA Y CONTROL DE LAS ENTIDADES SIN ÁNIMO DE LUCRO | L39: =C39=P39 -> TRUE | M39: =J39=AH39 -> TRUE | P39: VACANTE DEFINITIVA | R39: VACANTE DEFINITIVA | X39: VACANTE DEFINITIVA | AB39: VACANTE DEFINITIVA | AC39: PROFESIONAL | AD39: PROFESIONAL ESPECIALIZADO | AE39: 222 | AF39: 27 | AG39: =AE39&"-"&AF39 -> 222-27 | AH39: DIRECCIÓN DISTRITAL DE INSPECCIÓN VIGILANCIA Y CONTROL DE LAS ENTIDADES SIN ÁNIMO DE LUCRO | AI39: =AG39=I39 -> TRUE
A40: 39 | C40: VACANTE DEFINITIVA | D40: 3 | E40: PROFESIONAL | F40: PROFESIONAL ESPECIALIZADO | G40: 222 | H40: 27 | I40: =G40&"-"&H40 -> 222-27 | J40: DIRECCIÓN DISTRITAL DE INSPECCIÓN VIGILANCIA Y CONTROL DE LAS ENTIDADES SIN ÁNIMO DE LUCRO | L40: =C40=P40 -> TRUE | M40: =J40=AH40 -> TRUE | P40: VACANTE DEFINITIVA | R40: VACANTE DEFINITIVA | X40: VACANTE DEFINITIVA | AB40: VACANTE DEFINITIVA | AC40: PROFESIONAL | AD40: PROFESIONAL ESPECIALIZADO | AE40: 222 | AF40: 27 | AG40: =AE40&"-"&AF40 -> 222-27 | AH40: DIRECCIÓN DISTRITAL DE INSPECCIÓN VIGILANCIA Y CONTROL DE LAS ENTIDADES SIN ÁNIMO DE LUCRO | AI40: =AG40=I40 -> TRUE
...

Sheet PLANTA INICIAL (2)
B1: CC | C1: NOMBRE | D1: N | E1: NIVEL | F1: NOMENCLATURA_ADMIN | G1: CÓDIGO | H1: GRADO | J1: DEPENDENCIA | K1: NOMBRAMIENTO | N1: ID PERNO | AK1: DEPENDENCIA DEL CARGO
A2: 15 | C2: VACANTE DEFINITIVA | D2: 2 | E2: ASESOR | F2: JEFE DE OFICINA | G2: 115 | H2: 6 | I2: =G2&"-"&H2 -> 115-6 | J2: OFICINA ASESORA DE PLANEACIÓN | L2: =C2=P2 -> TRUE | M2: =J2=AH2 -> TRUE | N2: 11 | P2: VACANTE DEFINITIVA | R2: VACANTE DEFINITIVA | X2: VACANTE DEFINITIVA | AB2: VACANTE DEFINITIVA | AC2: ASESOR | AD2: JEFE DE OFICINA | AE2: 115 | AF2: 6 | AG2: =AE2&"-"&AF2 -> 115-6 | AH2: OFICINA ASESORA DE PLANEACIÓN | AI2: =AG2=I2 -> TRUE | AK2: OFICINA ASESORA DE PLANEACIÓN | AL2: =J2=AK2 -> TRUE
A3: 16 | C3: VACANTE DEFINITIVA | D3: 2 | E3: ASESOR | F3: JEFE DE OFICINA | G3: 115 | H3: 6 | I3: =G3&"-"&H3 -> 115-6 | J3: OFICINA DE LAS TECNOLOGÍAS DE LA INFORMACIÓN Y LAS COMUNICACIONES | L3: =C3=P3 -> FALSE | M3: =J3=AH3 -> FALSE | N3: 171 | O3: 19498970 | P3: OJEDA MONCAYO DIEGO EMILIO | Q3: LIBRE NOMBRAMIENTO Y REMOCIÓN | R3: NOMBRAMIENTO ORDINARIO | S3: 42622 | T3: 42622 | U3: HOMBRE | V3: 59 | X3: VACANTE DEFINITIVA | AB3: OCUPADO | AC3: ASESOR | AD3: JEFE DE OFICINA | AE3: 115 | AF3: 6 | AG3: =AE3&"-"&AF3 -> 115-6 | AH3: OFICINA DE TECNOLOGÍA DE LA INFORMACIÓN, SISTEMAS Y COMUNICACIONES | AI3: =AG3=I3 -> TRUE | AK3: OFICINA DE LAS TECNOLOGÍAS DE LA INFORMACIÓN Y LAS COMUNICACIONES | AL3: =J3=AK3 -> TRUE
A4: 10 | B4: 1085262099 | C4: BURBANO SÁNCHEZ MARÍA ANGÉLICA | D4: 2 | E4: ASESOR | F4: ASESOR | G4: 105 | H4: 5 | I4: =G4&"-"&H4 -> 105-5 | J4: DESPACHO SECRETARÍA JURÍDICA | K4: LIBRE NOMBRAMIENTO | L4: =C4=P4 -> FALSE | M4: =J4=AH4 -> FALSE | N4: 12 | O4: 79317479 | P4: CORDOBA DELGADO JOSE IGNACIO | Q4: LIBRE NOMBRAMIENTO Y REMOCIÓN | R4: NOMBRAMIENTO ORDINARIO | S4: 42632 | T4: 42632 | U4: HOMBRE | V4: 60 | X4: VACANTE DEFINITIVA | AB4: OCUPADO | AC4: ASESOR | AD4: ASESOR | AE4: 105 | AF4: 5 | AG4: =AE4&"-"&AF4 -> 105-5 | AH4: DESPACHO | AI4: =AG4=I4 -> TRUE | AK4: DESPACHO SECRETARÍA JURÍDICA | AL4: =J4=AK4 -> TRUE
A5: 11 | B5: 80040965 | C5: CUELLAR TRUJILLO PEDRO ANDRÉS | D5: 2 | E5: ASESOR | F5: ASESOR | G5: 105 | H5: 5 | I5: =G5&"-"&H5 -> 105-5 | J5: DESPACHO SECRETARÍA JURÍDICA | K5: LIBRE NOMBRAMIENTO | L5: =C5=P5 -> TRUE | M5: =J5=AH5 -> FALSE | N5: 13 | O5: 80040965 | P5: CUELLAR TRUJILLO PEDRO ANDRÉS | Q5: LIBRE NOMBRAMIENTO Y REMOCIÓN | R5: NOMBRAMIENTO ORDINARIO | S5: 42585 | T5: 42401 | U5: HOMBRE | V5: 39 | AB5: OCUPADO | AC5: ASESOR | AD5: ASESOR | AE5: 105 | AF5: 5 | AG5: =AE5&"-"&AF5 -> 105-5 | AH5: DESPACHO | AI5: =AG5=I5 -> TRUE | AK5: DESPACHO SECRETARÍA JURÍDICA | AL5: =J5=AK5 -> TRUE
A6: 12 | B6: 72291125 | C6: ESPINOSA OTERO ANDRES MAURICIO | D6: 2 | E6: ASESOR | F6: ASESOR | G6: 105 | H6: 5 | I6: =G6&"-"&H6 -> 105-5 | J6: DESPACHO SECRETARÍA JURÍDICA | K6: LIBRE NOMBRAMIENTO | L6: =C6=P6 -> TRUE | M6: =J6=AH6 -> FALSE | N6: 14 | O6: 72291125 | P6: ESPINOSA OTERO ANDRES MAURICIO | Q6: LIBRE NOMBRAMIENTO Y REMOCIÓN | R6: NOMBRAMIENTO ORDINARIO | S6: 42585 | T6: 42468 | U6: HOMBRE | V6: 38 | AB6: OCUPADO | AC6: ASESOR | AD6: ASESOR | AE6: 105 | AF6: 5 | AG6: =AE6&"-"&AF6 -> 105-5 | AH6: DESPACHO | AI6: =AG6=I6 -> TRUE | AK6: DESPACHO SECRETARÍA JURÍDICA | AL6: =J6=AK6 -> TRUE
A7: 13 | B7: 52233911 | C7: RODRÍGUEZ BARRERA NOHORA PATRICIA | D7: 2 | E7: ASESOR | F7: ASESOR | G7: 105 | H7: 5 | I7: =G7&"-"&H7 -> 105-5 | J7: DESPACHO SECRETARÍA JURÍDICA | K7: LIBRE NOMBRAMIENTO | L7: =C7=P7 -> TRUE | M7: =J7=AH7 -> FALSE | N7: 15 | O7: 52233911 | P7: RODRÍGUEZ BARRERA NOHORA PATRICIA | Q7: LIBRE NOMBRAMIENTO Y REMOCIÓN | R7: NOMBRAMIENTO ORDINARIO | S7: 42585 | T7: 35900 | U7: MUJER | V7: 44 | AB7: OCUPADO | AC7: ASESOR | AD7: ASESOR | AE7: 105 | AF7: 5 | AG7: =AE7&"-"&AF7 -> 105-5 | AH7: DESPACHO | AI7: =AG7=I7 -> TRUE | AK7: DESPACHO SECRETARÍA JURÍDICA | AL7: =J7=AK7 -> TRUE
